Workbook

Sheet Setup & Assumptions
B2: MTM Marketing — Commission Model Setup
B3: Yellow = inputs. HARD GATE: If a brand misses 100% sales target, ZERO commission for everyone on that brand.
B5: Financial Inputs | F5: Commission Pool Split (per Brand)
B6: Quarter being measured | C6: Apr–May–Jun 2026 | F6: Role | G6: Share | H6: Notes | K6: Brand–Role Assignments
B7: Commission pool as % of brand revenue | C7: 0.015 | F7: Account Manager | G7: 0.27 | H7: Strategy, organic, coordination | K7: Brand | L7: Media Buyer | M7: Designer | N7: Events Ran This Q?
F8: Media Buyer | G8: 0.27 | H8: Paid ads, CPL, | K8: VO2 Gym Ladies | L8: Amnay | M8: Jeff | N8: Yes
B9: Brand Sales Gate (HARD: 100% or zero) | F9: Marketing Manager | G9: 0.18 | H9: Highest, earns across all 8 brands | K9: VO2 Gym Men | L9: Ahmed | M9: Achraf | N9: Yes
B10: Brand Sales vs Target | C10: Min % | D10: Pool Unlock % | F10: Creative Director | G10: 0.07 | H10: Design direction (all brands) | K10: The Venue Ladies | L10: Salwa | M10: Alex | N10: Yes
B11: Below 100% (target missed) | C11: 0 | D11: 0 | F11: Designer | G11: 0.06 | H11: Brand-specific designer | K11: The Venue Men | L11: Ahmed | M11: Alex | N11: Yes
B12: 100 – 110% (target hit) | C12: 1 | D12: 1 | F12: Events / Sponsorship | G12: 0.06 | H12: Only if event ran this Q | K12: M Active Ladies | L12: Amnay | M12: Jeff | N12: Yes
B13: 111 – 125% (overperform) | C13: 1.11 | D13: 1.25 | F13: Videographer | G13: 0.04 | H13: Video production (all brands) | K13: M Active Club | L13: Ahmed | M13: Achraf | N13: Yes
B14: 126%+ (crushing it) | C14: 1.26 | D14: 1.5 | F14: Team Reserve | G14: 0.05 | H14: Buffer / bonus pool | K14: Aspire Active Dome | L14: Amnay | M14: Jeff | N14: Yes
F15: TOTAL | G15: =SUM(G7:G14) -> 1 | K15: Aspire Active Ladies | L15: Ahmed | M15: Jeff | N15: Yes
K16: Elite Swim Academy | L16: Salwa | M16: Alex | N16: Yes
F17: Individual KPI Modifier
F18: KPI Score | G18: Min % | H18: Modifier
B19: Team Roster | F19: Below 80% | G19: 0 | H19: 0
B20: Role | C20: Name | D20: Notes | F20: 80 – 94% | G20: 0.8 | H20: 0.75
B21: Marketing Manager | C21: Paola | D21: Earns from all brands | F21: 95 – 104% | G21: 0.95 | H21: 1
B22: Account Manager 1 | C22: Salta | D22: 3 brands | F22: 105 – 119% | G22: 1.05 | H22: 1.15
B23: Account Manager 2 | C23: Issa | D23: 3 brands | F23: 120%+ | G23: 1.2 | H23: 1.3
B24: Account Manager 3 | C24: Ruba | D24: 3 brands
B25: Media Buyer (Senior) | C25: Amnay | D25: Earns from all brands
B26: Media Buyer (Junior) | C26: Salwa | D26: 2 brands | F26: Growth Multipliers (AM Organic) | K26: Growth Multipliers (Media Buyer Paid)
B27: Media Buyer (Junior) | C27: Ahmed | D27: 3 brands | F27: Metric | G27: Multiplier | H27: How target is set | K27: Metric | L27: Multiplier | M27: How target is set
B28: Designer | C28: Jeff | D28: 3 brands | F28: Reach | G28: 1.3 | H28: Q Target = 6-mo monthly avg × 3 × 1.30 | K28: Messages (Leads) /Q | L28: 1.2 | M28: Target = 6-mo Q avg × 1.20
B29: Designer | C29: Achraf | D29: 3 brands | F29: Engagement Rate | G29: 0.05 | H29: Absolute target % (industry 4-6%) | K29: Cost per Message (CPL) | L29: 0.9 | M29: Target = 6-mo avg × 0.90 (inverted)
B30: Designer | C30: Alex | D30: 3 brands | F30: DM Inquiries | G30: 1.25 | H30: Q Target = 6-mo monthly avg × 3 × 1.25 | K30: Reach /Q | L30: 1.15 | M30: Target = 6-mo Q avg × 1.15
B31: Videographer | C31: Jaily | D31: Earns across all brands | F31: New Followers | G31: 1.15 | H31: Q Target = 6-mo monthly avg × 3 × 1.15 | K31: Awareness (Impressions) /Q | L31: 1.15 | M31: Target = 6-mo Q avg × 1.15
B32: Creative Director | C32: Omar | D32: Earns across all brands | F32: Saves | G32: 1.3 | H32: Q Target = 6-mo monthly avg × 3 × 1.30 | K32: Budget Pacing | L32: 1 | M32: Target = 100% adherence (±5%)
B33: Events / Sponsorship | C33: Janna | D33: Works across all brands | F33: Shares | G33: 1.3 | H33: Q Target = 6-mo monthly avg × 3 × 1.30 | K33: Creative Variations per Offer | L33: 3 | M33: Target variations per monthly offer (× 3 for quarter)
F34: Posting Consistency | G34: 12 | H34: Target posts/mo (× 3 for quarter)
F35: Content Mix Adherence | G35: 1 | H35: Target = 100% adherence

Sheet AM Organic KPIs
B2: Account Manager — Organic KPI Scorecard (Monthly: Apr–May–Jun 2026)
B3: GRAY cells = 6-mo monthly avg (input). Targets compound 30% MoM. April actuals pre-filled from Final KPI Organic file.
E5: TIER 1 — OUTCOME / VISIBILITY (60%) | AA5: TIER 3 — GROWTH (15%) | AL5: TIER 2 — ENGAGEMENT (25%) | BH5: WEIGHTED SCORE
E6: Reach | P6: Views | AA6: New Followers | AL6: Shares | AW6: Saves
B7: Brand | C7: Owner (AM) | D7: Followers | E7: 6-Mo Avg | F7: Apr Tgt | G7: Apr Act | H7: Apr % | I7: May Tgt | J7: May Act | K7: May % | L7: Jun Tgt | M7: Jun Act | N7: Jun % | O7: Q % | P7: 6-Mo Avg | Q7: Apr Tgt | R7: Apr Act | S7: Apr % | T7: May Tgt | U7: May Act | V7: May % | W7: Jun Tgt | X7: Jun Act | Y7: Jun % | Z7: Q % | AA7: 6-Mo Avg | AB7: Apr Tgt | AC7: Apr Act | AD7: Apr % | AE7: May Tgt | AF7: May Act | AG7: May % | AH7: Jun Tgt | AI7: Jun Act | AJ7: Jun % | AK7: Q % | AL7: 6-Mo Avg | AM7: Apr Tgt | AN7: Apr Act | AO7: Apr % | AP7: May Tgt | AQ7: May Act | AR7: May % | AS7: Jun Tgt | AT7: Jun Act | AU7: Jun % | AV7: Q % | AW7: 6-Mo Avg | AX7: Apr Tgt | AY7: Apr Act | AZ7: Apr % | BA7: May Tgt | BB7: May Act | BC7: May % | BD7: Jun Tgt | BE7: Jun Act | BF7: Jun % | BG7: Q % | BH7: Tier 1 | BI7: Tier 2 | BJ7: Tier 3 | BK7: Total | BL7: Modifier
B8: VO2 Gym Ladies | C8: Ruba | D8: 13900 | E8: 109798 | F8: =E8*1.3 -> 142737.4 | G8: 163445 | H8: =IFERROR(G8/F8,0) -> 1.1450748 | I8: =F8*1.3 -> 185558.62 | K8: =IFERROR(J8/I8,0) -> 0 | L8: =I8*1.3 -> 241226.21 | N8: =IFERROR(M8/L8,0) -> 0 | O8: =AVERAGE(H8,K8,N8) -> 0.3816916 | P8: 250834 | Q8: =P8*1.3 -> 326084.2 | R8: 222618 | S8: =IFERROR(R8/Q8,0) -> 0.68270097 | T8: =Q8*1.3 -> 423909.46 | V8: =IFERROR(U8/T8,0) -> 0 | W8: =T8*1.3 -> 551082.3 | Y8: =IFERROR(X8/W8,0) -> 0 | Z8: =AVERAGE(S8,V8,Y8) -> 0.22756699 | AA8: 34 | AB8: =AA8*1.3 -> 44.2 | AC8: 29 | AD8: =IFERROR(AC8/AB8,0) -> 0.6561086 | AE8: =AB8*1.3 -> 57.46 | AG8: =IFERROR(AF8/AE8,0) -> 0 | AH8: =AE8*1.3 -> 74.698 | AJ8: =IFERROR(AI8/AH8,0) -> 0 | AK8: =AVERAGE(AD8,AG8,AJ8) -> 0.21870287 | AL8: 1041 | AM8: =AL8*1.3 -> 1353.3 | AN8: 465 | AO8: =IFERROR(AN8/AM8,0) -> 0.34360452 | AP8: =AM8*1.3 -> 1759.29 | AR8: =IFERROR(AQ8/AP8,0) -> 0 | AS8: =AP8*1.3 -> 2287.077 | AU8: =IFERROR(AT8/AS8,0) -> 0 | AV8: =AVERAGE(AO8,AR8,AU8) -> 0.11453484 | AW8: 90 | AX8: =AW8*1.3 -> 117 | AY8: 132 | AZ8: =IFERROR(AY8/AX8,0) -> 1.1282051 | BA8: =AX8*1.3 -> 152.1 | BC8: =IFERROR(BB8/BA8,0) -> 0 | BD8: =BA8*1.3 -> 197.73 | BF8: =IFERROR(BE8/BD8,0) -> 0 | BG8: =AVERAGE(AZ8,BC8,BF8) -> 0.37606838 | BH8: =AVERAGE(O8,Z8) -> 0.3046293 | BI8: =AVERAGE(AV8,BG8) -> 0.24530161 | BJ8: =AK8 -> 0.21870287 | BK8: =BH8*0.6+BI8*0.25+BJ8*0.15 -> 0.27690841 | BL8: =IFERROR(LOOKUP(BK8,'Setup & Assumptions'!$G$19:$G$23,'Setup & Assumptions'!$H$19:$H$23),0) -> 0
B9: VO2 Gym Men | C9: Ruba | D9: 160 | E9: 160 | F9: =E9*1.3 -> 208 | H9: =IFERROR(G9/F9,0) -> 0 | I9: =F9*1.3 -> 270.4 | K9: =IFERROR(J9/I9,0) -> 0 | L9: =I9*1.3 -> 351.52 | N9: =IFERROR(M9/L9,0) -> 0 | O9: =AVERAGE(H9,K9,N9) -> 0 | P9: 0 | Q9: =P9*1.3 -> 0 | S9: =IFERROR(R9/Q9,0) -> 0 | T9: =Q9*1.3 -> 0 | V9: =IFERROR(U9/T9,0) -> 0 | W9: =T9*1.3 -> 0 | Y9: =IFERROR(X9/W9,0) -> 0 | Z9: =AVERAGE(S9,V9,Y9) -> 0 | AA9: 0 | AB9: =AA9*1.3 -> 0 | AD9: =IFERROR(AC9/AB9,0) -> 0 | AE9: =AB9*1.3 -> 0 | AG9: =IFERROR(AF9/AE9,0) -> 0 | AH9: =AE9*1.3 -> 0 | AJ9: =IFERROR(AI9/AH9,0) -> 0 | AK9: =AVERAGE(AD9,AG9,AJ9) -> 0 | AL9: 0 | AM9: =AL9*1.3 -> 0 | AO9: =IFERROR(AN9/AM9,0) -> 0 | AP9: =AM9*1.3 -> 0 | AR9: =IFERROR(AQ9/AP9,0) -> 0 | AS9: =AP9*1.3 -> 0 | AU9: =IFERROR(AT9/AS9,0) -> 0 | AV9: =AVERAGE(AO9,AR9,AU9) -> 0 | AW9: 0 | AX9: =AW9*1.3 -> 0 | AZ9: =IFERROR(AY9/AX9,0) -> 0 | BA9: =AX9*1.3 -> 0 | BC9: =IFERROR(BB9/BA9,0) -> 0 | BD9: =BA9*1.3 -> 0 | BF9: =IFERROR(BE9/BD9,0) -> 0 | BG9: =AVERAGE(AZ9,BC9,BF9) -> 0 | BH9: =AVERAGE(O9,Z9) -> 0 | BI9: =AVERAGE(AV9,BG9) -> 0 | BJ9: =AK9 -> 0 | BK9: =BH9*0.6+BI9*0.25+BJ9*0.15 -> 0 | BL9: =IFERROR(LOOKUP(BK9,'Setup & Assumptions'!$G$19:$G$23,'Setup & Assumptions'!$H$19:$H$23),0) -> 0
B10: The Venue Ladies | C10: Salta | D10: 32900 | E10: 56671 | F10: =E10*1.3 -> 73672.3 | G10: 104372 | H10: =IFERROR(G10/F10,0) -> 1.4167061 | I10: =F10*1.3 -> 95773.99 | K10: =IFERROR(J10/I10,0) -> 0 | L10: =I10*1.3 -> 124506.19 | N10: =IFERROR(M10/L10,0) -> 0 | O10: =AVERAGE(H10,K10,N10) -> 0.47223538 | P10: 122945 | Q10: =P10*1.3 -> 159828.5 | R10: 154624 | S10: =IFERROR(R10/Q10,0) -> 0.96743697 | T10: =Q10*1.3 -> 207777.05 | V10: =IFERROR(U10/T10,0) -> 0 | W10: =T10*1.3 -> 270110.17 | Y10: =IFERROR(X10/W10,0) -> 0 | Z10: =AVERAGE(S10,V10,Y10) -> 0.32247899 | AA10: 10 | AB10: =AA10*1.3 -> 13 | AC10: 24 | AD10: =IFERROR(AC10/AB10,0) -> 1.8461538 | AE10: =AB10*1.3 -> 16.9 | AG10: =IFERROR(AF10/AE10,0) -> 0 | AH10: =AE10*1.3 -> 21.97 | AJ10: =IFERROR(AI10/AH10,0) -> 0 | AK10: =AVERAGE(AD10,AG10,AJ10) -> 0.61538462 | AL10: 120 | AM10: =AL10*1.3 -> 156 | AN10: 532 | AO10: =IFERROR(AN10/AM10,0) -> 3.4102564 | AP10: =AM10*1.3 -> 202.8 | AR10: =IFERROR(AQ10/AP10,0) -> 0 | AS10: =AP10*1.3 -> 263.64 | AU10: =IFERROR(AT10/AS10,0) -> 0 | AV10: =AVERAGE(AO10,AR10,AU10) -> 1.1367521 | AW10: 80 | AX10: =AW10*1.3 -> 104 | AY10: 224 | AZ10: =IFERROR(AY10/AX10,0) -> 2.1538462 | BA10: =AX10*1.3 -> 135.2 | BC10: =IFERROR(BB10/BA10,0) -> 0 | BD10: =BA10*1.3 -> 175.76 | BF10: =IFERROR(BE10/BD10,0) -> 0 | BG10: =AVERAGE(AZ10,BC10,BF10) -> 0.71794872 | BH10: =AVERAGE(O10,Z10) -> 0.39735719 | BI10: =AVERAGE(AV10,BG10) -> 0.92735043 | BJ10: =AK10 -> 0.61538462 | BK10: =BH10*0.6+BI10*0.25+BJ10*0.15 -> 0.56255961 | BL10: =IFERROR(LOOKUP(BK10,'Setup & Assumptions'!$G$19:$G$23,'Setup & Assumptions'!$H$19:$H$23),0) -> 0
B11: The Venue Men | C11: Issa | D11: 15500 | E11: 30182 | F11: =E11*1.3 -> 39236.6 | G11: 13248 | H11: =IFERROR(G11/F11,0) -> 0.33764393 | I11: =F11*1.3 -> 51007.58 | K11: =IFERROR(J11/I11,0) -> 0 | L11: =I11*1.3 -> 66309.854 | N11: =IFERROR(M11/L11,0) -> 0 | O11: =AVERAGE(H11,K11,N11) -> 0.11254798 | P11: 64215 | Q11: =P11*1.3 -> 83479.5 | R11: 43771 | S11: =IFERROR(R11/Q11,0) -> 0.52433232 | T11: =Q11*1.3 -> 108523.35 | V11: =IFERROR(U11/T11,0) -> 0 | W11: =T11*1.3 -> 141080.36 | Y11: =IFERROR(X11/W11,0) -> 0 | Z11: =AVERAGE(S11,V11,Y11) -> 0.17477744 | AA11: 6 | AB11: =AA11*1.3 -> 7.8 | AC11: 11 | AD11: =IFERROR(AC11/AB11,0) -> 1.4102564 | AE11: =AB11*1.3 -> 10.14 | AG11: =IFERROR(AF11/AE11,0) -> 0 | AH11: =AE11*1.3 -> 13.182 | AJ11: =IFERROR(AI11/AH11,0) -> 0 | AK11: =AVERAGE(AD11,AG11,AJ11) -> 0.47008547 | AL11: 104 | AM11: =AL11*1.3 -> 135.2 | AN11: 178 | AO11: =IFERROR(AN11/AM11,0) -> 1.316568 | AP11: =AM11*1.3 -> 175.76 | AR11: =IFERROR(AQ11/AP11,0) -> 0 | AS11: =AP11*1.3 -> 228.488 | AU11: =IFERROR(AT11/AS11,0) -> 0 | AV11: =AVERAGE(AO11,AR11,AU11) -> 0.43885602 | AW11: 33 | AX11: =AW11*1.3 -> 42.9 | AY11: 28 | AZ11: =IFERROR(AY11/AX11,0) -> 0.65268065 | BA11: =AX11*1.3 -> 55.77 | BC11: =IFERROR(BB11/BA11,0) -> 0 | BD11: =BA11*1.3 -> 72.501 | BF11: =IFERROR(BE11/BD11,0) -> 0 | BG11: =AVERAGE(AZ11,BC11,BF11) -> 0.21756022 | BH11: =AVERAGE(O11,Z11) -> 0.14366271 | BI11: =AVERAGE(AV11,BG11) -> 0.32820812 | BJ11: =AK11 -> 0.47008547 | BK11: =BH11*0.6+BI11*0.25+BJ11*0.15 -> 0.23876248 | BL11: =IFERROR(LOOKUP(BK11,'Setup & Assumptions'!$G$19:$G$23,'Setup & Assumptions'!$H$19:$H$23),0) -> 0
B12: M Active Ladies | C12: Salta | D12: 30600 | E12: 55249 | F12: =E12*1.3 -> 71823.7 | G12: 61278 | H12: =IFERROR(G12/F12,0) -> 0.85317242 | I12: =F12*1.3 -> 93370.81 | K12: =IFERROR(J12/I12,0) -> 0 | L12: =I12*1.3 -> 121382.05 | N12: =IFERROR(M12/L12,0) -> 0 | O12: =AVERAGE(H12,K12,N12) -> 0.28439081 | P12: 174106 | Q12: =P12*1.3 -> 226337.8 | R12: 87974 | S12: =IFERROR(R12/Q12,0) -> 0.38868452 | T12: =Q12*1.3 -> 294239.14 | V12: =IFERROR(U12/T12,0) -> 0 | W12: =T12*1.3 -> 382510.88 | Y12: =IFERROR(X12/W12,0) -> 0 | Z12: =AVERAGE(S12,V12,Y12) -> 0.12956151 | AA12: 13 | AB12: =AA12*1.3 -> 16.9 | AC12: 21 | AD12: =IFERROR(AC12/AB12,0) -> 1.2426036 | AE12: =AB12*1.3 -> 21.97 | AG12: =IFERROR(AF12/AE12,0) -> 0 | AH12: =AE12*1.3 -> 28.561 | AJ12: =IFERROR(AI12/AH12,0) -> 0 | AK12: =AVERAGE(AD12,AG12,AJ12) -> 0.41420118 | AL12: 140 | AM12: =AL12*1.3 -> 182 | AN12: 189 | AO12: =IFERROR(AN12/AM12,0) -> 1.0384615 | AP12: =AM12*1.3 -> 236.6 | AR12: =IFERROR(AQ12/AP12,0) -> 0 | AS12: =AP12*1.3 -> 307.58 | AU12: =IFERROR(AT12/AS12,0) -> 0 | AV12: =AVERAGE(AO12,AR12,AU12) -> 0.34615385 | AW12: 85 | AX12: =AW12*1.3 -> 110.5 | AY12: 118 | AZ12: =IFERROR(AY12/AX12,0) -> 1.0678733 | BA12: =AX12*1.3 -> 143.65 | BC12: =IFERROR(BB12/BA12,0) -> 0 | BD12: =BA12*1.3 -> 186.745 | BF12: =IFERROR(BE12/BD12,0) -> 0 | BG12: =AVERAGE(AZ12,BC12,BF12) -> 0.35595777 | BH12: =AVERAGE(O12,Z12) -> 0.20697616 | BI12: =AVERAGE(AV12,BG12) -> 0.35105581 | BJ12: =AK12 -> 0.41420118 | BK12: =BH12*0.6+BI12*0.25+BJ12*0.15 -> 0.27407982 | BL12: =IFERROR(LOOKUP(BK12,'Setup & Assumptions'!$G$19:$G$23,'Setup & Assumptions'!$H$19:$H$23),0) -> 0
B13: M Active Club | C13: Salta | D13: 18600 | E13: 40978 | F13: =E13*1.3 -> 53271.4 | G13: 23245 | H13: =IFERROR(G13/F13,0) -> 0.43635046 | I13: =F13*1.3 -> 69252.82 | K13: =IFERROR(J13/I13,0) -> 0 | L13: =I13*1.3 -> 90028.666 | N13: =IFERROR(M13/L13,0) -> 0 | O13: =AVERAGE(H13,K13,N13) -> 0.14545015 | P13: 88684 | Q13: =P13*1.3 -> 115289.2 | R13: 45139 | S13: =IFERROR(R13/Q13,0) -> 0.39152843 | T13: =Q13*1.3 -> 149875.96 | V13: =IFERROR(U13/T13,0) -> 0 | W13: =T13*1.3 -> 194838.75 | Y13: =IFERROR(X13/W13,0) -> 0 | Z13: =AVERAGE(S13,V13,Y13) -> 0.13050948 | AA13: 8 | AB13: =AA13*1.3 -> 10.4 | AC13: 6 | AD13: =IFERROR(AC13/AB13,0) -> 0.57692308 | AE13: =AB13*1.3 -> 13.52 | AG13: =IFERROR(AF13/AE13,0) -> 0 | AH13: =AE13*1.3 -> 17.576 | AJ13: =IFERROR(AI13/AH13,0) -> 0 | AK13: =AVERAGE(AD13,AG13,AJ13) -> 0.19230769 | AL13: 82 | AM13: =AL13*1.3 -> 106.6 | AN13: 116 | AO13: =IFERROR(AN13/AM13,0) -> 1.0881801 | AP13: =AM13*1.3 -> 138.58 | AR13: =IFERROR(AQ13/AP13,0) -> 0 | AS13: =AP13*1.3 -> 180.154 | AU13: =IFERROR(AT13/AS13,0) -> 0 | AV13: =AVERAGE(AO13,AR13,AU13) -> 0.3627267 | AW13: 25 | AX13: =AW13*1.3 -> 32.5 | AY13: 58 | AZ13: =IFERROR(AY13/AX13,0) -> 1.7846154 | BA13: =AX13*1.3 -> 42.25 | BC13: =IFERROR(BB13/BA13,0) -> 0 | BD13: =BA13*1.3 -> 54.925 | BF13: =IFERROR(BE13/BD13,0) -> 0 | BG13: =AVERAGE(AZ13,BC13,BF13) -> 0.59487179 | BH13: =AVERAGE(O13,Z13) -> 0.13797982 | BI13: =AVERAGE(AV13,BG13) -> 0.47879925 | BJ13: =AK13 -> 0.19230769 | BK13: =BH13*0.6+BI13*0.25+BJ13*0.15 -> 0.23133386 | BL13: =IFERROR(LOOKUP(BK13,'Setup & Assumptions'!$G$19:$G$23,'Setup & Assumptions'!$H$19:$H$23),0) -> 0
B14: Aspire Active Dome | C14: Issa | D14: 16500 | E14: 22830 | F14: =E14*1.3 -> 29679 | G14: 29015 | H14: =IFERROR(G14/F14,0) -> 0.97762728 | I14: =F14*1.3 -> 38582.7 | K14: =IFERROR(J14/I14,0) -> 0 | L14: =I14*1.3 -> 50157.51 | N14: =IFERROR(M14/L14,0) -> 0 | O14: =AVERAGE(H14,K14,N14) -> 0.32587576 | P14: 44071 | Q14: =P14*1.3 -> 57292.3 | R14: 41189 | S14: =IFERROR(R14/Q14,0) -> 0.71892733 | T14: =Q14*1.3 -> 74479.99 | V14: =IFERROR(U14/T14,0) -> 0 | W14: =T14*1.3 -> 96823.987 | Y14: =IFERROR(X14/W14,0) -> 0 | Z14: =AVERAGE(S14,V14,Y14) -> 0.23964244 | AA14: 5 | AB14: =AA14*1.3 -> 6.5 | AC14: 14 | AD14: =IFERROR(AC14/AB14,0) -> 2.1538462 | AE14: =AB14*1.3 -> 8.45 | AG14: =IFERROR(AF14/AE14,0) -> 0 | AH14: =AE14*1.3 -> 10.985 | AJ14: =IFERROR(AI14/AH14,0) -> 0 | AK14: =AVERAGE(AD14,AG14,AJ14) -> 0.71794872 | AL14: 81 | AM14: =AL14*1.3 -> 105.3 | AN14: 192 | AO14: =IFERROR(AN14/AM14,0) -> 1.8233618 | AP14: =AM14*1.3 -> 136.89 | AR14: =IFERROR(AQ14/AP14,0) -> 0 | AS14: =AP14*1.3 -> 177.957 | AU14: =IFERROR(AT14/AS14,0) -> 0 | AV14: =AVERAGE(AO14,AR14,AU14) -> 0.60778727 | AW14: 15 | AX14: =AW14*1.3 -> 19.5 | AY14: 45 | AZ14: =IFERROR(AY14/AX14,0) -> 2.3076923 | BA14: =AX14*1.3 -> 25.35 | BC14: =IFERROR(BB14/BA14,0) -> 0 | BD14: =BA14*1.3 -> 32.955 | BF14: =IFERROR(BE14/BD14,0) -> 0 | BG14: =AVERAGE(AZ14,BC14,BF14) -> 0.76923077 | BH14: =AVERAGE(O14,Z14) -> 0.2827591 | BI14: =AVERAGE(AV14,BG14) -> 0.68850902 | BJ14: =AK14 -> 0.71794872 | BK14: =BH14*0.6+BI14*0.25+BJ14*0.15 -> 0.44947502 | BL14: =IFERROR(LOOKUP(BK14,'Setup & Assumptions'!$G$19:$G$23,'Setup & Assumptions'!$H$19:$H$23),0) -> 0
B15: Aspire Active Ladies | C15: Ruba | D15: 16500 | E15: 22830 | F15: =E15*1.3 -> 29679 | G15: 29015 | H15: =IFERROR(G15/F15,0) -> 0.97762728 | I15: =F15*1.3 -> 38582.7 | K15: =IFERROR(J15/I15,0) -> 0 | L15: =I15*1.3 -> 50157.51 | N15: =IFERROR(M15/L15,0) -> 0 | O15: =AVERAGE(H15,K15,N15) -> 0.32587576 | P15: 44071 | Q15: =P15*1.3 -> 57292.3 | R15: 41188 | S15: =IFERROR(R15/Q15,0) -> 0.71890987 | T15: =Q15*1.3 -> 74479.99 | V15: =IFERROR(U15/T15,0) -> 0 | W15: =T15*1.3 -> 96823.987 | Y15: =IFERROR(X15/W15,0) -> 0 | Z15: =AVERAGE(S15,V15,Y15) -> 0.23963662 | AA15: 5 | AB15: =AA15*1.3 -> 6.5 | AC15: 13 | AD15: =IFERROR(AC15/AB15,0) -> 2 | AE15: =AB15*1.3 -> 8.45 | AG15: =IFERROR(AF15/AE15,0) -> 0 | AH15: =AE15*1.3 -> 10.985 | AJ15: =IFERROR(AI15/AH15,0) -> 0 | AK15: =AVERAGE(AD15,AG15,AJ15) -> 0.66666667 | AL15: 81 | AM15: =AL15*1.3 -> 105.3 | AN15: 191 | AO15: =IFERROR(AN15/AM15,0) -> 1.8138651 | AP15: =AM15*1.3 -> 136.89 | AR15: =IFERROR(AQ15/AP15,0) -> 0 | AS15: =AP15*1.3 -> 177.957 | AU15: =IFERROR(AT15/AS15,0) -> 0 | AV15: =AVERAGE(AO15,AR15,AU15) -> 0.60462172 | AW15: 15 | AX15: =AW15*1.3 -> 19.5 | AY15: 44 | AZ15: =IFERROR(AY15/AX15,0) -> 2.2564103 | BA15: =AX15*1.3 -> 25.35 | BC15: =IFERROR(BB15/BA15,0) -> 0 | BD15: =BA15*1.3 -> 32.955 | BF15: =IFERROR(BE15/BD15,0) -> 0 | BG15: =AVERAGE(AZ15,BC15,BF15) -> 0.75213675 | BH15: =AVERAGE(O15,Z15) -> 0.28275619 | BI15: =AVERAGE(AV15,BG15) -> 0.67837923 | BJ15: =AK15 -> 0.66666667 | BK15: =BH15*0.6+BI15*0.25+BJ15*0.15 -> 0.43924852 | BL15: =IFERROR(LOOKUP(BK15,'Setup & Assumptions'!$G$19:$G$23,'Setup & Assumptions'!$H$19:$H$23),0) -> 0
B16: Elite Swim Academy | C16: Issa | D16: 27300 | E16: 29231 | F16: =E16*1.3 -> 38000.3 | G16: 28056 | H16: =IFERROR(G16/F16,0) -> 0.73830996 | I16: =F16*1.3 -> 49400.39 | K16: =IFERROR(J16/I16,0) -> 0 | L16: =I16*1.3 -> 64220.507 | N16: =IFERROR(M16/L16,0) -> 0 | O16: =AVERAGE(H16,K16,N16) -> 0.24610332 | P16: 54195 | Q16: =P16*1.3 -> 70453.5 | R16: 151959 | S16: =IFERROR(R16/Q16,0) -> 2.1568694 | T16: =Q16*1.3 -> 91589.55 | V16: =IFERROR(U16/T16,0) -> 0 | W16: =T16*1.3 -> 119066.42 | Y16: =IFERROR(X16/W16,0) -> 0 | Z16: =AVERAGE(S16,V16,Y16) -> 0.71895647 | AA16: 14 | AB16: =AA16*1.3 -> 18.2 | AC16: 10 | AD16: =IFERROR(AC16/AB16,0) -> 0.54945055 | AE16: =AB16*1.3 -> 23.66 | AG16: =IFERROR(AF16/AE16,0) -> 0 | AH16: =AE16*1.3 -> 30.758 | AJ16: =IFERROR(AI16/AH16,0) -> 0 | AK16: =AVERAGE(AD16,AG16,AJ16) -> 0.18315018 | AL16: 87 | AM16: =AL16*1.3 -> 113.1 | AN16: 1023 | AO16: =IFERROR(AN16/AM16,0) -> 9.0450928 | AP16: =AM16*1.3 -> 147.03 | AR16: =IFERROR(AQ16/AP16,0) -> 0 | AS16: =AP16*1.3 -> 191.139 | AU16: =IFERROR(AT16/AS16,0) -> 0 | AV16: =AVERAGE(AO16,AR16,AU16) -> 3.0150309 | AW16: 63 | AX16: =AW16*1.3 -> 81.9 | AY16: 52 | AZ16: =IFERROR(AY16/AX16,0) -> 0.63492063 | BA16: =AX16*1.3 -> 106.47 | BC16: =IFERROR(BB16/BA16,0) -> 0 | BD16: =BA16*1.3 -> 138.411 | BF16: =IFERROR(BE16/BD16,0) -> 0 | BG16: =AVERAGE(AZ16,BC16,BF16) -> 0.21164021 | BH16: =AVERAGE(O16,Z16) -> 0.4825299 | BI16: =AVERAGE(AV16,BG16) -> 1.6133356 | BJ16: =AK16 -> 0.18315018 | BK16: =BH16*0.6+BI16*0.25+BJ16*0.15 -> 0.72032436 | BL16: =IFERROR(LOOKUP(BK16,'Setup & Assumptions'!$G$19:$G$23,'Setup & Assumptions'!$H$19:$H$23),0) -> 0
B23: Account Manager — Organic KPI Scorecard (Monthly:JUN–JUL–AUG 2026)
B24: GRAY cells = 6-mo monthly avg (input). Targets compound 30% MoM. April actuals pre-filled from Final KPI Organic file.
E26: TIER 1 — OUTCOME / VISIBILITY (60%) | AA26: TIER 3 — GROWTH (15%) | AL26: TIER 2 — ENGAGEMENT (25%) | BH26: WEIGHTED SCORE
E27: Reach | P27: Views | AA27: New Followers | AL27: Shares | AW27: Saves
B28: Brand | C28: Owner (AM) | D28: Followers | E28: 6-Mo Avg | F28: Apr Tgt | G28: Apr Act | H28: Apr % | I28: May Tgt | J28: May Act | K28: May % | L28: Jun Tgt | M28: Jun Act | N28: Jun % | O28: Q % | P28: 6-Mo Avg | Q28: Apr Tgt | R28: Apr Act | S28: Apr % | T28: May Tgt | U28: May Act | V28: May % | W28: Jun Tgt | X28: Jun Act | Y28: Jun % | Z28: Q % | AA28: 6-Mo Avg | AB28: Apr Tgt | AC28: Apr Act | AD28: Apr % | AE28: May Tgt | AF28: May Act | AG28: May % | AH28: Jun Tgt | AI28: Jun Act | AJ28: Jun % | AK28: Q % | AL28: 6-Mo Avg | AM28: Apr Tgt | AN28: Apr Act | AO28: Apr % | AP28: May Tgt | AQ28: May Act | AR28: May % | AS28: Jun Tgt | AT28: Jun Act | AU28: Jun % | AV28: Q % | AW28: 6-Mo Avg | AX28: Apr Tgt | AY28: Apr Act | AZ28: Apr % | BA28: May Tgt | BB28: May Act | BC28: May % | BD28: Jun Tgt | BE28: Jun Act | BF28: Jun % | BG28: Q % | BH28: Tier 1 | BI28: Tier 2 | BJ28: Tier 3 | BK28: Total | BL28: Modifier
B29: VO2 Gym Ladies | C29: Ruba | D29: 13900 | E29: 109798 | F29: =E29*1.3 -> 142737.4 | G29: 163445 | H29: =IFERROR(G29/F29,0) -> 1.1450748 | I29: =F29*1.3 -> 185558.62 | K29: =IFERROR(J29/I29,0) -> 0 | L29: =I29*1.3 -> 241226.21 | N29: =IFERROR(M29/L29,0) -> 0 | O29: =AVERAGE(H29,K29,N29) -> 0.3816916 | P29: 250834 | Q29: =P29*1.3 -> 326084.2 | R29: 222618 | S29: =IFERROR(R29/Q29,0) -> 0.68270097 | T29: =Q29*1.3 -> 423909.46 | V29: =IFERROR(U29/T29,0) -> 0 | W29: =T29*1.3 -> 551082.3 | Y29: =IFERROR(X29/W29,0) -> 0 | Z29: =AVERAGE(S29,V29,Y29) -> 0.22756699 | AA29: 34 | AB29: =AA29*1.3 -> 44.2 | AC29: 29 | AD29: =IFERROR(AC29/AB29,0) -> 0.6561086 | AE29: =AB29*1.3 -> 57.46 | AG29: =IFERROR(AF29/AE29,0) -> 0 | AH29: =AE29*1.3 -> 74.698 | AJ29: =IFERROR(AI29/AH29,0) -> 0 | AK29: =AVERAGE(AD29,AG29,AJ29) -> 0.21870287 | AL29: 1041 | AM29: =AL29*1.3 -> 1353.3 | AN29: 465 | AO29: =IFERROR(AN29/AM29,0) -> 0.34360452 | AP29: =AM29*1.3 -> 1759.29 | AR29: =IFERROR(AQ29/AP29,0) -> 0 | AS29: =AP29*1.3 -> 2287.077 | AU29: =IFERROR(AT29/AS29,0) -> 0 | AV29: =AVERAGE(AO29,AR29,AU29) -> 0.11453484 | AW29: 90 | AX29: =AW29*1.3 -> 117 | AY29: 132 | AZ29: =IFERROR(AY29/AX29,0) -> 1.1282051 | BA29: =AX29*1.3 -> 152.1 | BC29: =IFERROR(BB29/BA29,0) -> 0 | BD29: =BA29*1.3 -> 197.73 | BF29: =IFERROR(BE29/BD29,0) -> 0 | BG29: =AVERAGE(AZ29,BC29,BF29) -> 0.37606838 | BH29: =AVERAGE(O29,Z29) -> 0.3046293 | BI29: =AVERAGE(AV29,BG29) -> 0.24530161 | BJ29: =AK29 -> 0.21870287 | BK29: =BH29*0.6+BI29*0.25+BJ29*0.15 -> 0.27690841 | BL29: =IFERROR(LOOKUP(BK29,'Setup & Assumptions'!$G$19:$G$23,'Setup & Assumptions'!$H$19:$H$23),0) -> 0
B30: VO2 Gym Men | C30: Ruba | D30: 160 | E30: 160 | F30: =E30*1.3 -> 208 | H30: =IFERROR(G30/F30,0) -> 0 | I30: =F30*1.3 -> 270.4 | K30: =IFERROR(J30/I30,0) -> 0 | L30: =I30*1.3 -> 351.52 | N30: =IFERROR(M30/L30,0) -> 0 | O30: =AVERAGE(H30,K30,N30) -> 0 | P30: 0 | Q30: =P30*1.3 -> 0 | S30: =IFERROR(R30/Q30,0) -> 0 | T30: =Q30*1.3 -> 0 | V30: =IFERROR(U30/T30,0) -> 0 | W30: =T30*1.3 -> 0 | Y30: =IFERROR(X30/W30,0) -> 0 | Z30: =AVERAGE(S30,V30,Y30) -> 0 | AA30: 0 | AB30: =AA30*1.3 -> 0 | AD30: =IFERROR(AC30/AB30,0) -> 0 | AE30: =AB30*1.3 -> 0 | AG30: =IFERROR(AF30/AE30,0) -> 0 | AH30: =AE30*1.3 -> 0 | AJ30: =IFERROR(AI30/AH30,0) -> 0 | AK30: =AVERAGE(AD30,AG30,AJ30) -> 0 | AL30: 0 | AM30: =AL30*1.3 -> 0 | AO30: =IFERROR(AN30/AM30,0) -> 0 | AP30: =AM30*1.3 -> 0 | AR30: =IFERROR(AQ30/AP30,0) -> 0 | AS30: =AP30*1.3 -> 0 | AU30: =IFERROR(AT30/AS30,0) -> 0 | AV30: =AVERAGE(AO30,AR30,AU30) -> 0 | AW30: 0 | AX30: =AW30*1.3 -> 0 | AZ30: =IFERROR(AY30/AX30,0) -> 0 | BA30: =AX30*1.3 -> 0 | BC30: =IFERROR(BB30/BA30,0) -> 0 | BD30: =BA30*1.3 -> 0 | BF30: =IFERROR(BE30/BD30,0) -> 0 | BG30: =AVERAGE(AZ30,BC30,BF30) -> 0 | BH30: =AVERAGE(O30,Z30) -> 0 | BI30: =AVERAGE(AV30,BG30) -> 0 | BJ30: =AK30 -> 0 | BK30: =BH30*0.6+BI30*0.25+BJ30*0.15 -> 0 | BL30: =IFERROR(LOOKUP(BK30,'Setup & Assumptions'!$G$19:$G$23,'Setup & Assumptions'!$H$19:$H$23),0) -> 0
B31: The Venue Ladies | C31: Salta | D31: 32900 | E31: 56671 | F31: =E31*1.3 -> 73672.3 | G31: 104372 | H31: =IFERROR(G31/F31,0) -> 1.4167061 | I31: =F31*1.3 -> 95773.99 | K31: =IFERROR(J31/I31,0) -> 0 | L31: =I31*1.3 -> 124506.19 | N31: =IFERROR(M31/L31,0) -> 0 | O31: =AVERAGE(H31,K31,N31) -> 0.47223538 | P31: 122945 | Q31: =P31*1.3 -> 159828.5 | R31: 154624 | S31: =IFERROR(R31/Q31,0) -> 0.96743697 | T31: =Q31*1.3 -> 207777.05 | V31: =IFERROR(U31/T31,0) -> 0 | W31: =T31*1.3 -> 270110.17 | Y31: =IFERROR(X31/W31,0) -> 0 | Z31: =AVERAGE(S31,V31,Y31) -> 0.32247899 | AA31: 10 | AB31: =AA31*1.3 -> 13 | AC31: 24 | AD31: =IFERROR(AC31/AB31,0) -> 1.8461538 | AE31: =AB31*1.3 -> 16.9 | AG31: =IFERROR(AF31/AE31,0) -> 0 | AH31: =AE31*1.3 -> 21.97 | AJ31: =IFERROR(AI31/AH31,0) -> 0 | AK31: =AVERAGE(AD31,AG31,AJ31) -> 0.61538462 | AL31: 120 | AM31: =AL31*1.3 -> 156 | AN31: 532 | AO31: =IFERROR(AN31/AM31,0) -> 3.4102564 | AP31: =AM31*1.3 -> 202.8 | AR31: =IFERROR(AQ31/AP31,0) -> 0 | AS31: =AP31*1.3 -> 263.64 | AU31: =IFERROR(AT31/AS31,0) -> 0 | AV31: =AVERAGE(AO31,AR31,AU31) -> 1.1367521 | AW31: 80 | AX31: =AW31*1.3 -> 104 | AY31: 224 | AZ31: =IFERROR(AY31/AX31,0) -> 2.1538462 | BA31: =AX31*1.3 -> 135.2 | BC31: =IFERROR(BB31/BA31,0) -> 0 | BD31: =BA31*1.3 -> 175.76 | BF31: =IFERROR(BE31/BD31,0) -> 0 | BG31: =AVERAGE(AZ31,BC31,BF31) -> 0.71794872 | BH31: =AVERAGE(O31,Z31) -> 0.39735719 | BI31: =AVERAGE(AV31,BG31) -> 0.92735043 | BJ31: =AK31 -> 0.61538462 | BK31: =BH31*0.6+BI31*0.25+BJ31*0.15 -> 0.56255961 | BL31: =IFERROR(LOOKUP(BK31,'Setup & Assumptions'!$G$19:$G$23,'Setup & Assumptions'!$H$19:$H$23),0) -> 0
B32: The Venue Men | C32: Issa | D32: 15500 | E32: 30182 | F32: =E32*1.3 -> 39236.6 | G32: 13248 | H32: =IFERROR(G32/F32,0) -> 0.33764393 | I32: =F32*1.3 -> 51007.58 | K32: =IFERROR(J32/I32,0) -> 0 | L32: =I32*1.3 -> 66309.854 | N32: =IFERROR(M32/L32,0) -> 0 | O32: =AVERAGE(H32,K32,N32) -> 0.11254798 | P32: 64215 | Q32: =P32*1.3 -> 83479.5 | R32: 43771 | S32: =IFERROR(R32/Q32,0) -> 0.52433232 | T32: =Q32*1.3 -> 108523.35 | V32: =IFERROR(U32/T32,0) -> 0 | W32: =T32*1.3 -> 141080.36 | Y32: =IFERROR(X32/W32,0) -> 0 | Z32: =AVERAGE(S32,V32,Y32) -> 0.17477744 | AA32: 6 | AB32: =AA32*1.3 -> 7.8 | AC32: 11 | AD32: =IFERROR(AC32/AB32,0) -> 1.4102564 | AE32: =AB32*1.3 -> 10.14 | AG32: =IFERROR(AF32/AE32,0) -> 0 | AH32: =AE32*1.3 -> 13.182 | AJ32: =IFERROR(AI32/AH32,0) -> 0 | AK32: =AVERAGE(AD32,AG32,AJ32) -> 0.47008547 | AL32: 104 | AM32: =AL32*1.3 -> 135.2 | AN32: 178 | AO32: =IFERROR(AN32/AM32,0) -> 1.316568 | AP32: =AM32*1.3 -> 175.76 | AR32: =IFERROR(AQ32/AP32,0) -> 0 | AS32: =AP32*1.3 -> 228.488 | AU32: =IFERROR(AT32/AS32,0) -> 0 | AV32: =AVERAGE(AO32,AR32,AU32) -> 0.43885602 | AW32: 33 | AX32: =AW32*1.3 -> 42.9 | AY32: 28 | AZ32: =IFERROR(AY32/AX32,0) -> 0.65268065 | BA32: =AX32*1.3 -> 55.77 | BC32: =IFERROR(BB32/BA32,0) -> 0 | BD32: =BA32*1.3 -> 72.501 | BF32: =IFERROR(BE32/BD32,0) -> 0 | BG32: =AVERAGE(AZ32,BC32,BF32) -> 0.21756022 | BH32: =AVERAGE(O32,Z32) -> 0.14366271 | BI32: =AVERAGE(AV32,BG32) -> 0.32820812 | BJ32: =AK32 -> 0.47008547 | BK32: =BH32*0.6+BI32*0.25+BJ32*0.15 -> 0.23876248 | BL32: =IFERROR(LOOKUP(BK32,'Setup & Assumptions'!$G$19:$G$23,'Setup & Assumptions'!$H$19:$H$23),0) -> 0
B33: M Active Ladies | C33: Salta | D33: 30600 | E33: 55249 | F33: =E33*1.3 -> 71823.7 | G33: 61278 | H33: =IFERROR(G33/F33,0) -> 0.85317242 | I33: =F33*1.3 -> 93370.81 | K33: =IFERROR(J33/I33,0) -> 0 | L33: =I33*1.3 -> 121382.05 | N33: =IFERROR(M33/L33,0) -> 0 | O33: =AVERAGE(H33,K33,N33) -> 0.28439081 | P33: 174106 | Q33: =P33*1.3 -> 226337.8 | R33: 87974 | S33: =IFERROR(R33/Q33,0) -> 0.38868452 | T33: =Q33*1.3 -> 294239.14 | V33: =IFERROR(U33/T33,0) -> 0 | W33: =T33*1.3 -> 382510.88 | Y33: =IFERROR(X33/W33,0) -> 0 | Z33: =AVERAGE(S33,V33,Y33) -> 0.12956151 | AA33: 13 | AB33: =AA33*1.3 -> 16.9 | AC33: 21 | AD33: =IFERROR(AC33/AB33,0) -> 1.2426036 | AE33: =AB33*1.3 -> 21.97 | AG33: =IFERROR(AF33/AE33,0) -> 0 | AH33: =AE33*1.3 -> 28.561 | AJ33: =IFERROR(AI33/AH33,0) -> 0 | AK33: =AVERAGE(AD33,AG33,AJ33) -> 0.41420118 | AL33: 140 | AM33: =AL33*1.3 -> 182 | AN33: 189 | AO33: =IFERROR(AN33/AM33,0) -> 1.0384615 | AP33: =AM33*1.3 -> 236.6 | AR33: =IFERROR(AQ33/AP33,0) -> 0 | AS33: =AP33*1.3 -> 307.58 | AU33: =IFERROR(AT33/AS33,0) -> 0 | AV33: =AVERAGE(AO33,AR33,AU33) -> 0.34615385 | AW33: 85 | AX33: =AW33*1.3 -> 110.5 | AY33: 118 | AZ33: =IFERROR(AY33/AX33,0) -> 1.0678733 | BA33: =AX33*1.3 -> 143.65 | BC33: =IFERROR(BB33/BA33,0) -> 0 | BD33: =BA33*1.3 -> 186.745 | BF33: =IFERROR(BE33/BD33,0) -> 0 | BG33: =AVERAGE(AZ33,BC33,BF33) -> 0.35595777 | BH33: =AVERAGE(O33,Z33) -> 0.20697616 | BI33: =AVERAGE(AV33,BG33) -> 0.35105581 | BJ33: =AK33 -> 0.41420118 | BK33: =BH33*0.6+BI33*0.25+BJ33*0.15 -> 0.27407982 | BL33: =IFERROR(LOOKUP(BK33,'Setup & Assumptions'!$G$19:$G$23,'Setup & Assumptions'!$H$19:$H$23),0) -> 0
B34: M Active Club | C34: Salta | D34: 18600 | E34: 40978 | F34: =E34*1.3 -> 53271.4 | G34: 23245 | H34: =IFERROR(G34/F34,0) -> 0.43635046 | I34: =F34*1.3 -> 69252.82 | K34: =IFERROR(J34/I34,0) -> 0 | L34: =I34*1.3 -> 90028.666 | N34: =IFERROR(M34/L34,0) -> 0 | O34: =AVERAGE(H34,K34,N34) -> 0.14545015 | P34: 88684 | Q34: =P34*1.3 -> 115289.2 | R34: 45139 | S34: =IFERROR(R34/Q34,0) -> 0.39152843 | T34: =Q34*1.3 -> 149875.96 | V34: =IFERROR(U34/T34,0) -> 0 | W34: =T34*1.3 -> 194838.75 | Y34: =IFERROR(X34/W34,0) -> 0 | Z34: =AVERAGE(S34,V34,Y34) -> 0.13050948 | AA34: 8 | AB34: =AA34*1.3 -> 10.4 | AC34: 6 | AD34: =IFERROR(AC34/AB34,0) -> 0.57692308 | AE34: =AB34*1.3 -> 13.52 | AG34: =IFERROR(AF34/AE34,0) -> 0 | AH34: =AE34*1.3 -> 17.576 | AJ34: =IFERROR(AI34/AH34,0) -> 0 | AK34: =AVERAGE(AD34,AG34,AJ34) -> 0.19230769 | AL34: 82 | AM34: =AL34*1.3 -> 106.6 | AN34: 116 | AO34: =IFERROR(AN34/AM34,0) -> 1.0881801 | AP34: =AM34*1.3 -> 138.58 | AR34: =IFERROR(AQ34/AP34,0) -> 0 | AS34: =AP34*1.3 -> 180.154 | AU34: =IFERROR(AT34/AS34,0) -> 0 | AV34: =AVERAGE(AO34,AR34,AU34) -> 0.3627267 | AW34: 25 | AX34: =AW34*1.3 -> 32.5 | AY34: 58 | AZ34: =IFERROR(AY34/AX34,0) -> 1.7846154 | BA34: =AX34*1.3 -> 42.25 | BC34: =IFERROR(BB34/BA34,0) -> 0 | BD34: =BA34*1.3 -> 54.925 | BF34: =IFERROR(BE34/BD34,0) -> 0 | BG34: =AVERAGE(AZ34,BC34,BF34) -> 0.59487179 | BH34: =AVERAGE(O34,Z34) -> 0.13797982 | BI34: =AVERAGE(AV34,BG34) -> 0.47879925 | BJ34: =AK34 -> 0.19230769 | BK34: =BH34*0.6+BI34*0.25+BJ34*0.15 -> 0.23133386 | BL34: =IFERROR(LOOKUP(BK34,'Setup & Assumptions'!$G$19:$G$23,'Setup & Assumptions'!$H$19:$H$23),0) -> 0
B35: Aspire Active Dome | C35: Issa | D35: 16500 | E35: 22830 | F35: =E35*1.3 -> 29679 | G35: 29015 | H35: =IFERROR(G35/F35,0) -> 0.97762728 | I35: =F35*1.3 -> 38582.7 | K35: =IFERROR(J35/I35,0) -> 0 | L35: =I35*1.3 -> 50157.51 | N35: =IFERROR(M35/L35,0) -> 0 | O35: =AVERAGE(H35,K35,N35) -> 0.32587576 | P35: 44071 | Q35: =P35*1.3 -> 57292.3 | R35: 41189 | S35: =IFERROR(R35/Q35,0) -> 0.71892733 | T35: =Q35*1.3 -> 74479.99 | V35: =IFERROR(U35/T35,0) -> 0 | W35: =T35*1.3 -> 96823.987 | Y35: =IFERROR(X35/W35,0) -> 0 | Z35: =AVERAGE(S35,V35,Y35) -> 0.23964244 | AA35: 5 | AB35: =AA35*1.3 -> 6.5 | AC35: 14 | AD35: =IFERROR(AC35/AB35,0) -> 2.1538462 | AE35: =AB35*1.3 -> 8.45 | AG35: =IFERROR(AF35/AE35,0) -> 0 | AH35: =AE35*1.3 -> 10.985 | AJ35: =IFERROR(AI35/AH35,0) -> 0 | AK35: =AVERAGE(AD35,AG35,AJ35) -> 0.71794872 | AL35: 81 | AM35: =AL35*1.3 -> 105.3 | AN35: 192 | AO35: =IFERROR(AN35/AM35,0) -> 1.8233618 | AP35: =AM35*1.3 -> 136.89 | AR35: =IFERROR(AQ35/AP35,0) -> 0 | AS35: =AP35*1.3 -> 177.957 | AU35: =IFERROR(AT35/AS35,0) -> 0 | AV35: =AVERAGE(AO35,AR35,AU35) -> 0.60778727 | AW35: 15 | AX35: =AW35*1.3 -> 19.5 | AY35: 45 | AZ35: =IFERROR(AY35/AX35,0) -> 2.3076923 | BA35: =AX35*1.3 -> 25.35 | BC35: =IFERROR(BB35/BA35,0) -> 0 | BD35: =BA35*1.3 -> 32.955 | BF35: =IFERROR(BE35/BD35,0) -> 0 | BG35: =AVERAGE(AZ35,BC35,BF35) -> 0.76923077 | BH35: =AVERAGE(O35,Z35) -> 0.2827591 | BI35: =AVERAGE(AV35,BG35) -> 0.68850902 | BJ35: =AK35 -> 0.71794872 | BK35: =BH35*0.6+BI35*0.25+BJ35*0.15 -> 0.44947502 | BL35: =IFERROR(LOOKUP(BK35,'Setup & Assumptions'!$G$19:$G$23,'Setup & Assumptions'!$H$19:$H$23),0) -> 0
B36: Aspire Active Ladies | C36: Ruba | D36: 16500 | E36: 22830 | F36: =E36*1.3 -> 29679 | G36: 29015 | H36: =IFERROR(G36/F36,0) -> 0.97762728 | I36: =F36*1.3 -> 38582.7 | K36: =IFERROR(J36/I36,0) -> 0 | L36: =I36*1.3 -> 50157.51 | N36: =IFERROR(M36/L36,0) -> 0 | O36: =AVERAGE(H36,K36,N36) -> 0.32587576 | P36: 44071 | Q36: =P36*1.3 -> 57292.3 | R36: 41188 | S36: =IFERROR(R36/Q36,0) -> 0.71890987 | T36: =Q36*1.3 -> 74479.99 | V36: =IFERROR(U36/T36,0) -> 0 | W36: =T36*1.3 -> 96823.987 | Y36: =IFERROR(X36/W36,0) -> 0 | Z36: =AVERAGE(S36,V36,Y36) -> 0.23963662 | AA36: 5 | AB36: =AA36*1.3 -> 6.5 | AC36: 13 | AD36: =IFERROR(AC36/AB36,0) -> 2 | AE36: =AB36*1.3 -> 8.45 | AG36: =IFERROR(AF36/AE36,0) -> 0 | AH36: =AE36*1.3 -> 10.985 | AJ36: =IFERROR(AI36/AH36,0) -> 0 | AK36: =AVERAGE(AD36,AG36,AJ36) -> 0.66666667 | AL36: 81 | AM36: =AL36*1.3 -> 105.3 | AN36: 191 | AO36: =IFERROR(AN36/AM36,0) -> 1.8138651 | AP36: =AM36*1.3 -> 136.89 | AR36: =IFERROR(AQ36/AP36,0) -> 0 | AS36: =AP36*1.3 -> 177.957 | AU36: =IFERROR(AT36/AS36,0) -> 0 | AV36: =AVERAGE(AO36,AR36,AU36) -> 0.60462172 | AW36: 15 | AX36: =AW36*1.3 -> 19.5 | AY36: 44 | AZ36: =IFERROR(AY36/AX36,0) -> 2.2564103 | BA36: =AX36*1.3 -> 25.35 | BC36: =IFERROR(BB36/BA36,0) -> 0 | BD36: =BA36*1.3 -> 32.955 | BF36: =IFERROR(BE36/BD36,0) -> 0 | BG36: =AVERAGE(AZ36,BC36,BF36) -> 0.75213675 | BH36: =AVERAGE(O36,Z36) -> 0.28275619 | BI36: =AVERAGE(AV36,BG36) -> 0.67837923 | BJ36: =AK36 -> 0.66666667 | BK36: =BH36*0.6+BI36*0.25+BJ36*0.15 -> 0.43924852 | BL36: =IFERROR(LOOKUP(BK36,'Setup & Assumptions'!$G$19:$G$23,'Setup & Assumptions'!$H$19:$H$23),0) -> 0
B37: Elite Swim Academy | C37: Issa | D37: 27300 | E37: 29231 | F37: =E37*1.3 -> 38000.3 | G37: 28056 | H37: =IFERROR(G37/F37,0) -> 0.73830996 | I37: =F37*1.3 -> 49400.39 | K37: =IFERROR(J37/I37,0) -> 0 | L37: =I37*1.3 -> 64220.507 | N37: =IFERROR(M37/L37,0) -> 0 | O37: =AVERAGE(H37,K37,N37) -> 0.24610332 | P37: 54195 | Q37: =P37*1.3 -> 70453.5 | R37: 151959 | S37: =IFERROR(R37/Q37,0) -> 2.1568694 | T37: =Q37*1.3 -> 91589.55 | V37: =IFERROR(U37/T37,0) -> 0 | W37: =T37*1.3 -> 119066.42 | Y37: =IFERROR(X37/W37,0) -> 0 | Z37: =AVERAGE(S37,V37,Y37) -> 0.71895647 | AA37: 14 | AB37: =AA37*1.3 -> 18.2 | AC37: 10 | AD37: =IFERROR(AC37/AB37,0) -> 0.54945055 | AE37: =AB37*1.3 -> 23.66 | AG37: =IFERROR(AF37/AE37,0) -> 0 | AH37: =AE37*1.3 -> 30.758 | AJ37: =IFERROR(AI37/AH37,0) -> 0 | AK37: =AVERAGE(AD37,AG37,AJ37) -> 0.18315018 | AL37: 87 | AM37: =AL37*1.3 -> 113.1 | AN37: 1023 | AO37: =IFERROR(AN37/AM37,0) -> 9.0450928 | AP37: =AM37*1.3 -> 147.03 | AR37: =IFERROR(AQ37/AP37,0) -> 0 | AS37: =AP37*1.3 -> 191.139 | AU37: =IFERROR(AT37/AS37,0) -> 0 | AV37: =AVERAGE(AO37,AR37,AU37) -> 3.0150309 | AW37: 63 | AX37: =AW37*1.3 -> 81.9 | AY37: 52 | AZ37: =IFERROR(AY37/AX37,0) -> 0.63492063 | BA37: =AX37*1.3 -> 106.47 | BC37: =IFERROR(BB37/BA37,0) -> 0 | BD37: =BA37*1.3 -> 138.411 | BF37: =IFERROR(BE37/BD37,0) -> 0 | BG37: =AVERAGE(AZ37,BC37,BF37) -> 0.21164021 | BH37: =AVERAGE(O37,Z37) -> 0.4825299 | BI37: =AVERAGE(AV37,BG37) -> 1.6133356 | BJ37: =AK37 -> 0.18315018 | BK37: =BH37*0.6+BI37*0.25+BJ37*0.15 -> 0.72032436 | BL37: =IFERROR(LOOKUP(BK37,'Setup & Assumptions'!$G$19:$G$23,'Setup & Assumptions'!$H$19:$H$23),0) -> 0

Sheet Media Buyer Paid KPIs
B2: Media Buyer — Paid KPI Scorecard (Quarterly) — Meta Ads
B3: GRAY = 6-mo QUARTERLY avg from Meta Ads Report. Inverted (CPL) — lower is better.
D5: TIER 1 — OUTCOME (60%) | L5: TIER 2 — VISIBILITY (25%) | T5: TIER 3 — PROCESS (15%) | AB5: WEIGHTED SCORE
D6: Messages (Leads) /Q | H6: Cost per Message (CPL) | L6: Reach /Q | P6: Awareness (Impressions) /Q | T6: Budget Pacing | X6: Creative Variations /Q
B7: Brand | C7: Owner (MB) | D7: 6-Mo Avg | E7: Target | F7: Actual | G7: % | H7: 6-Mo Avg | I7: Target | J7: Actual | K7: % | L7: 6-Mo Avg | M7: Target | N7: Actual | O7: % | P7: 6-Mo Avg | Q7: Target | R7: Actual | S7: % | T7: 6-Mo Avg | U7: Target | V7: Actual | W7: % | X7: 6-Mo Avg | Y7: Target | Z7: Actual | AA7: % | AB7: Tier 1 | AC7: Tier 2 | AD7: Tier 3 | AE7: Total | AF7: Modifier
B8: VO2 Gym Ladies | C8: Amnay | D8: 232 | E8: =D8*'Setup & Assumptions'!$L$28 -> 278.4 | F8: 464 | G8: =IFERROR(F8/E8,0) -> 1.6666667 | H8: 81 | I8: =H8*'Setup & Assumptions'!$L$29 -> 72.9 | J8: 80 | K8: =IFERROR(I8/J8,0) -> 0.91125 | L8: 441282 | M8: =L8*'Setup & Assumptions'!$L$30 -> 507474.3 | N8: 622131 | O8: =IFERROR(N8/M8,0) -> 1.225936 | P8: 1819524 | Q8: =P8*'Setup & Assumptions'!$L$31 -> 2092452.6 | R8: 3182264 | S8: =IFERROR(R8/Q8,0) -> 1.5208297 | T8: 1 | U8: ='Setup & Assumptions'!$L$32 -> 1 | W8: =IFERROR(MAX(0,1-ABS(V8-U8)/U8),0) -> 0 | X8: 2 | Y8: ='Setup & Assumptions'!$L$33*3 -> 9 | AA8: =IFERROR(Z8/Y8,0) -> 0 | AB8: =AVERAGE(G8,K8) -> 1.2889583 | AC8: =AVERAGE(O8,S8) -> 1.3733828 | AD8: =AVERAGE(W8,AA8) -> 0 | AE8: =AB8*0.6+AC8*0.25+AD8*0.15 -> 1.1167207 | AF8: =IFERROR(LOOKUP(AE8,'Setup & Assumptions'!$G$19:$G$23,'Setup & Assumptions'!$H$19:$H$23),0) -> 1.15
B9: VO2 Gym Men | C9: Ahmed | D9: 232 | E9: =D9*'Setup & Assumptions'!$L$28 -> 278.4 | G9: =IFERROR(F9/E9,0) -> 0 | H9: 0 | I9: =H9*'Setup & Assumptions'!$L$29 -> 0 | K9: =IFERROR(I9/J9,0) -> 0 | L9: 0 | M9: =L9*'Setup & Assumptions'!$L$30 -> 0 | O9: =IFERROR(N9/M9,0) -> 0 | P9: 0 | Q9: =P9*'Setup & Assumptions'!$L$31 -> 0 | S9: =IFERROR(R9/Q9,0) -> 0 | T9: 1 | U9: ='Setup & Assumptions'!$L$32 -> 1 | W9: =IFERROR(MAX(0,1-ABS(V9-U9)/U9),0) -> 0 | X9: 2 | Y9: ='Setup & Assumptions'!$L$33*3 -> 9 | AA9: =IFERROR(Z9/Y9,0) -> 0 | AB9: =AVERAGE(G9,K9) -> 0 | AC9: =AVERAGE(O9,S9) -> 0 | AD9: =AVERAGE(W9,AA9) -> 0 | AE9: =AB9*0.6+AC9*0.25+AD9*0.15 -> 0 | AF9: =IFERROR(LOOKUP(AE9,'Setup & Assumptions'!$G$19:$G$23,'Setup & Assumptions'!$H$19:$H$23),0) -> 0
B10: The Venue Ladies | C10: Salwa | D10: 2701 | E10: =D10*'Setup & Assumptions'!$L$28 -> 3241.2 | F10: 855 | G10: =IFERROR(F10/E10,0) -> 0.26379119 | H10: 38 | I10: =H10*'Setup & Assumptions'!$L$29 -> 34.2 | J10: 40 | K10: =IFERROR(I10/J10,0) -> 0.855 | L10: 2051850 | M10: =L10*'Setup & Assumptions'!$L$30 -> 2359627.5 | N10: 1072220 | O10: =IFERROR(N10/M10,0) -> 0.45440223 | P10: 7007695 | Q10: =P10*'Setup & Assumptions'!$L$31 -> 8058849.2 | R10: 4642764 | S10: =IFERROR(R10/Q10,0) -> 0.57610756 | T10: 1 | U10: ='Setup & Assumptions'!$L$32 -> 1 | W10: =IFERROR(MAX(0,1-ABS(V10-U10)/U10),0) -> 0 | X10: 2 | Y10: ='Setup & Assumptions'!$L$33*3 -> 9 | AA10: =IFERROR(Z10/Y10,0) -> 0 | AB10: =AVERAGE(G10,K10) -> 0.55939559 | AC10: =AVERAGE(O10,S10) -> 0.5152549 | AD10: =AVERAGE(W10,AA10) -> 0 | AE10: =AB10*0.6+AC10*0.25+AD10*0.15 -> 0.46445108 | AF10: =IFERROR(LOOKUP(AE10,'Setup & Assumptions'!$G$19:$G$23,'Setup & Assumptions'!$H$19:$H$23),0) -> 0
B11: The Venue Men | C11: Ahmed | D11: 2516 | E11: =D11*'Setup & Assumptions'!$L$28 -> 3019.2 | F11: 998 | G11: =IFERROR(F11/E11,0) -> 0.33055114 | H11: 38 | I11: =H11*'Setup & Assumptions'!$L$29 -> 34.2 | J11: 33 | K11: =IFERROR(I11/J11,0) -> 1.0363636 | L11: 3464539 | M11: =L11*'Setup & Assumptions'!$L$30 -> 3984219.8 | N11: 1268409 | O11: =IFERROR(N11/M11,0) -> 0.31835818 | P11: 9374989 | Q11: =P11*'Setup & Assumptions'!$L$31 -> 10781237 | R11: 5247351 | S11: =IFERROR(R11/Q11,0) -> 0.48671139 | T11: 1 | U11: ='Setup & Assumptions'!$L$32 -> 1 | W11: =IFERROR(MAX(0,1-ABS(V11-U11)/U11),0) -> 0 | X11: 2 | Y11: ='Setup & Assumptions'!$L$33*3 -> 9 | AA11: =IFERROR(Z11/Y11,0) -> 0 | AB11: =AVERAGE(G11,K11) -> 0.68345739 | AC11: =AVERAGE(O11,S11) -> 0.40253479 | AD11: =AVERAGE(W11,AA11) -> 0 | AE11: =AB11*0.6+AC11*0.25+AD11*0.15 -> 0.51070813 | AF11: =IFERROR(LOOKUP(AE11,'Setup & Assumptions'!$G$19:$G$23,'Setup & Assumptions'!$H$19:$H$23),0) -> 0
B12: M Active Ladies | C12: Amnay | D12: 4506 | E12: =D12*'Setup & Assumptions'!$L$28 -> 5407.2 | F12: 1750 | G12: =IFERROR(F12/E12,0) -> 0.32364255 | H12: 24 | I12: =H12*'Setup & Assumptions'!$L$29 -> 21.6 | J12: 19 | K12: =IFERROR(I12/J12,0) -> 1.1368421 | L12: 3937873 | M12: =L12*'Setup & Assumptions'!$L$30 -> 4528553.9 | N12: 3171562 | O12: =IFERROR(N12/M12,0) -> 0.70034762 | P12: 11195755 | Q12: =P12*'Setup & Assumptions'!$L$31 -> 12875118 | R12: 8721783 | S12: =IFERROR(R12/Q12,0) -> 0.67741382 | T12: 1 | U12: ='Setup & Assumptions'!$L$32 -> 1 | W12: =IFERROR(MAX(0,1-ABS(V12-U12)/U12),0) -> 0 | X12: 2 | Y12: ='Setup & Assumptions'!$L$33*3 -> 9 | AA12: =IFERROR(Z12/Y12,0) -> 0 | AB12: =AVERAGE(G12,K12) -> 0.73024233 | AC12: =AVERAGE(O12,S12) -> 0.68888072 | AD12: =AVERAGE(W12,AA12) -> 0 | AE12: =AB12*0.6+AC12*0.25+AD12*0.15 -> 0.61036558 | AF12: =IFERROR(LOOKUP(AE12,'Setup & Assumptions'!$G$19:$G$23,'Setup & Assumptions'!$H$19:$H$23),0) -> 0
B13: M Active Club | C13: Ahmed | D13: 4955 | E13: =D13*'Setup & Assumptions'!$L$28 -> 5946 | F13: 1359 | G13: =IFERROR(F13/E13,0) -> 0.22855701 | H13: 21 | I13: =H13*'Setup & Assumptions'!$L$29 -> 18.9 | J13: 26 | K13: =IFERROR(I13/J13,0) -> 0.72692308 | L13: 3796340 | M13: =L13*'Setup & Assumptions'!$L$30 -> 4365791 | N13: 1199874 | O13: =IFERROR(N13/M13,0) -> 0.27483542 | P13: 17591795 | Q13: =P13*'Setup & Assumptions'!$L$31 -> 20230564 | R13: 3451716 | S13: =IFERROR(R13/Q13,0) -> 0.17061887 | T13: 1 | U13: ='Setup & Assumptions'!$L$32 -> 1 | W13: =IFERROR(MAX(0,1-ABS(V13-U13)/U13),0) -> 0 | X13: 2 | Y13: ='Setup & Assumptions'!$L$33*3 -> 9 | AA13: =IFERROR(Z13/Y13,0) -> 0 | AB13: =AVERAGE(G13,K13) -> 0.47774005 | AC13: =AVERAGE(O13,S13) -> 0.22272714 | AD13: =AVERAGE(W13,AA13) -> 0 | AE13: =AB13*0.6+AC13*0.25+AD13*0.15 -> 0.34232581 | AF13: =IFERROR(LOOKUP(AE13,'Setup & Assumptions'!$G$19:$G$23,'Setup & Assumptions'!$H$19:$H$23),0) -> 0
B14: Aspire Active Dome | C14: Amnay | D14: 1426 | E14: =D14*'Setup & Assumptions'!$L$28 -> 1711.2 | F14: 470 | G14: =IFERROR(F14/E14,0) -> 0.27466106 | H14: 32 | I14: =H14*'Setup & Assumptions'!$L$29 -> 28.8 | J14: 28 | K14: =IFERROR(I14/J14,0) -> 1.0285714 | L14: 3005543 | M14: =L14*'Setup & Assumptions'!$L$30 -> 3456374.4 | N14: 1643862 | O14: =IFERROR(N14/M14,0) -> 0.47560298 | P14: 7484965 | Q14: =P14*'Setup & Assumptions'!$L$31 -> 8607709.8 | R14: 5046989 | S14: =IFERROR(R14/Q14,0) -> 0.58633355 | T14: 1 | U14: ='Setup & Assumptions'!$L$32 -> 1 | W14: =IFERROR(MAX(0,1-ABS(V14-U14)/U14),0) -> 0 | X14: 2 | Y14: ='Setup & Assumptions'!$L$33*3 -> 9 | AA14: =IFERROR(Z14/Y14,0) -> 0 | AB14: =AVERAGE(G14,K14) -> 0.65161624 | AC14: =AVERAGE(O14,S14) -> 0.53096827 | AD14: =AVERAGE(W14,AA14) -> 0 | AE14: =AB14*0.6+AC14*0.25+AD14*0.15 -> 0.52371181 | AF14: =IFERROR(LOOKUP(AE14,'Setup & Assumptions'!$G$19:$G$23,'Setup & Assumptions'!$H$19:$H$23),0) -> 0
B15: Aspire Active Ladies | C15: Ahmed | D15: 1642 | E15: =D15*'Setup & Assumptions'!$L$28 -> 1970.4 | F15: 504 | G15: =IFERROR(F15/E15,0) -> 0.25578563 | H15: 60 | I15: =H15*'Setup & Assumptions'!$L$29 -> 54 | J15: 63 | K15: =IFERROR(I15/J15,0) -> 0.85714286 | L15: 3363584 | M15: =L15*'Setup & Assumptions'!$L$30 -> 3868121.6 | N15: 1102104 | O15: =IFERROR(N15/M15,0) -> 0.28491969 | P15: 11139747 | Q15: =P15*'Setup & Assumptions'!$L$31 -> 12810709 | R15: 4312657 | S15: =IFERROR(R15/Q15,0) -> 0.33664468 | T15: 1 | U15: ='Setup & Assumptions'!$L$32 -> 1 | W15: =IFERROR(MAX(0,1-ABS(V15-U15)/U15),0) -> 0 | X15: 2 | Y15: ='Setup & Assumptions'!$L$33*3 -> 9 | AA15: =IFERROR(Z15/Y15,0) -> 0 | AB15: =AVERAGE(G15,K15) -> 0.55646424 | AC15: =AVERAGE(O15,S15) -> 0.31078218 | AD15: =AVERAGE(W15,AA15) -> 0 | AE15: =AB15*0.6+AC15*0.25+AD15*0.15 -> 0.41157409 | AF15: =IFERROR(LOOKUP(AE15,'Setup & Assumptions'!$G$19:$G$23,'Setup & Assumptions'!$H$19:$H$23),0) -> 0
B16: Elite Swim Academy | C16: Salwa | D16: 1928 | E16: =D16*'Setup & Assumptions'!$L$28 -> 2313.6 | F16: 917 | G16: =IFERROR(F16/E16,0) -> 0.39635201 | H16: 48 | I16: =H16*'Setup & Assumptions'!$L$29 -> 43.2 | J16: 38 | K16: =IFERROR(I16/J16,0) -> 1.1368421 | L16: 3918532 | M16: =L16*'Setup & Assumptions'!$L$30 -> 4506311.8 | N16: 2479260 | O16: =IFERROR(N16/M16,0) -> 0.55017498 | P16: 11242334 | Q16: =P16*'Setup & Assumptions'!$L$31 -> 12928684 | R16: 6857983 | S16: =IFERROR(R16/Q16,0) -> 0.5304471 | T16: 1 | U16: ='Setup & Assumptions'!$L$32 -> 1 | W16: =IFERROR(MAX(0,1-ABS(V16-U16)/U16),0) -> 0 | X16: 2 | Y16: ='Setup & Assumptions'!$L$33*3 -> 9 | AA16: =IFERROR(Z16/Y16,0) -> 0 | AB16: =AVERAGE(G16,K16) -> 0.76659706 | AC16: =AVERAGE(O16,S16) -> 0.54031104 | AD16: =AVERAGE(W16,AA16) -> 0 | AE16: =AB16*0.6+AC16*0.25+AD16*0.15 -> 0.59503599 | AF16: =IFERROR(LOOKUP(AE16,'Setup & Assumptions'!$G$19:$G$23,'Setup & Assumptions'!$H$19:$H$23),0) -> 0

Sheet Creative Team KPIs
B2: Creative Team — KPI Scorecard (Quarterly)
B3: GRAY = 6-mo avg. Inverted: Revisions, Brief Turnaround (lower=better). Creative Performance = avg ER (organic) or CTR (paid). Output Volume moved to Q3 plan.
D5: TIER 1 — PERFORMANCE (60%) | P5: TIER 2 — EXECUTION (25%) | X5: TIER 3 — QUALITY (15%) | AF5: WEIGHTED SCORE
D6: Creative Performance (ER/CTR) | H6: Top-Performer Rate | L6: Brand Consistency | P6: On-Time Delivery % | T6: Revision Rounds | X6: Brief Turnaround (days) | AB6: Team Feedback Score (/10)
B7: Person | C7: Role | D7: 6-Mo Avg | E7: Target | F7: Actual | G7: % | H7: 6-Mo Avg | I7: Target | J7: Actual | K7: % | L7: 6-Mo Avg | M7: Target | N7: Actual | O7: % | P7: 6-Mo Avg | Q7: Target | R7: Actual | S7: % | T7: 6-Mo Avg | U7: Target | V7: Actual | W7: % | X7: 6-Mo Avg | Y7: Target | Z7: Actual | AA7: % | AB7: 6-Mo Avg | AC7: Target | AD7: Actual | AE7: % | AF7: Tier 1 | AG7: Tier 2 | AH7: Tier 3 | AI7: Total | AJ7: Modifier
B8: CD | C8: Creative Director | D8: 0.03 | E8: =D8*1.1 -> 0.033 | G8: =IFERROR(F8/E8,0) -> 0 | H8: 0.2 | I8: =0.25 -> 0.25 | K8: =IFERROR(J8/I8,0) -> 0 | L8: 0.85 | M8: =0.95 -> 0.95 | O8: =IFERROR(N8/M8,0) -> 0 | P8: 0.85 | Q8: =0.95 -> 0.95 | S8: =IFERROR(R8/Q8,0) -> 0 | T8: 3 | U8: =2 -> 2 | W8: =IFERROR(U8/V8,0) -> 0 | X8: 4 | Y8: =3 -> 3 | AA8: =IFERROR(Y8/Z8,0) -> 0 | AB8: 7.5 | AC8: =8 -> 8 | AE8: =IFERROR(AD8/AC8,0) -> 0 | AF8: =AVERAGE(G8,K8,O8) -> 0 | AG8: =AVERAGE(S8,W8) -> 0 | AH8: =AVERAGE(AA8,AE8) -> 0 | AI8: =AF8*0.6+AG8*0.25+AH8*0.15 -> 0 | AJ8: =IFERROR(LOOKUP(AI8,'Setup & Assumptions'!$G$19:$G$23,'Setup & Assumptions'!$H$19:$H$23),0) -> 0
B9: Jaily | C9: Videographer | D9: 0.03 | E9: =D9*1.1 -> 0.033 | G9: =IFERROR(F9/E9,0) -> 0 | H9: 0.2 | I9: =0.25 -> 0.25 | K9: =IFERROR(J9/I9,0) -> 0 | L9: 0.85 | M9: =0.95 -> 0.95 | O9: =IFERROR(N9/M9,0) -> 0 | P9: 0.85 | Q9: =0.95 -> 0.95 | S9: =IFERROR(R9/Q9,0) -> 0 | T9: 3 | U9: =2 -> 2 | W9: =IFERROR(U9/V9,0) -> 0 | X9: 4 | Y9: =3 -> 3 | AA9: =IFERROR(Y9/Z9,0) -> 0 | AB9: 7.5 | AC9: =8 -> 8 | AE9: =IFERROR(AD9/AC9,0) -> 0 | AF9: =AVERAGE(G9,K9,O9) -> 0 | AG9: =AVERAGE(S9,W9) -> 0 | AH9: =AVERAGE(AA9,AE9) -> 0 | AI9: =AF9*0.6+AG9*0.25+AH9*0.15 -> 0 | AJ9: =IFERROR(LOOKUP(AI9,'Setup & Assumptions'!$G$19:$G$23,'Setup & Assumptions'!$H$19:$H$23),0) -> 0
B10: Jeff | C10: Designer | D10: 0.03 | E10: =D10*1.1 -> 0.033 | G10: =IFERROR(F10/E10,0) -> 0 | H10: 0.2 | I10: =0.25 -> 0.25 | K10: =IFERROR(J10/I10,0) -> 0 | L10: 0.85 | M10: =0.95 -> 0.95 | O10: =IFERROR(N10/M10,0) -> 0 | P10: 0.85 | Q10: =0.95 -> 0.95 | S10: =IFERROR(R10/Q10,0) -> 0 | T10: 3 | U10: =2 -> 2 | W10: =IFERROR(U10/V10,0) -> 0 | X10: 4 | Y10: =3 -> 3 | AA10: =IFERROR(Y10/Z10,0) -> 0 | AB10: 7.5 | AC10: =8 -> 8 | AE10: =IFERROR(AD10/AC10,0) -> 0 | AF10: =AVERAGE(G10,K10,O10) -> 0 | AG10: =AVERAGE(S10,W10) -> 0 | AH10: =AVERAGE(AA10,AE10) -> 0 | AI10: =AF10*0.6+AG10*0.25+AH10*0.15 -> 0 | AJ10: =IFERROR(LOOKUP(AI10,'Setup & Assumptions'!$G$19:$G$23,'Setup & Assumptions'!$H$19:$H$23),0) -> 0
B11: Achraf | C11: Designer | D11: 0.03 | E11: =D11*1.1 -> 0.033 | G11: =IFERROR(F11/E11,0) -> 0 | H11: 0.2 | I11: =0.25 -> 0.25 | K11: =IFERROR(J11/I11,0) -> 0 | L11: 0.85 | M11: =0.95 -> 0.95 | O11: =IFERROR(N11/M11,0) -> 0 | P11: 0.85 | Q11: =0.95 -> 0.95 | S11: =IFERROR(R11/Q11,0) -> 0 | T11: 3 | U11: =2 -> 2 | W11: =IFERROR(U11/V11,0) -> 0 | X11: 4 | Y11: =3 -> 3 | AA11: =IFERROR(Y11/Z11,0) -> 0 | AB11: 7.5 | AC11: =8 -> 8 | AE11: =IFERROR(AD11/AC11,0) -> 0 | AF11: =AVERAGE(G11,K11,O11) -> 0 | AG11: =AVERAGE(S11,W11) -> 0 | AH11: =AVERAGE(AA11,AE11) -> 0 | AI11: =AF11*0.6+AG11*0.25+AH11*0.15 -> 0 | AJ11: =IFERROR(LOOKUP(AI11,'Setup & Assumptions'!$G$19:$G$23,'Setup & Assumptions'!$H$19:$H$23),0) -> 0
B12: Alex | C12: Designer | D12: 0.03 | E12: =D12*1.1 -> 0.033 | G12: =IFERROR(F12/E12,0) -> 0 | H12: 0.2 | I12: =0.25 -> 0.25 | K12: =IFERROR(J12/I12,0) -> 0 | L12: 0.85 | M12: =0.95 -> 0.95 | O12: =IFERROR(N12/M12,0) -> 0 | P12: 0.85 | Q12: =0.95 -> 0.95 | S12: =IFERROR(R12/Q12,0) -> 0 | T12: 3 | U12: =2 -> 2 | W12: =IFERROR(U12/V12,0) -> 0 | X12: 4 | Y12: =3 -> 3 | AA12: =IFERROR(Y12/Z12,0) -> 0 | AB12: 7.5 | AC12: =8 -> 8 | AE12: =IFERROR(AD12/AC12,0) -> 0 | AF12: =AVERAGE(G12,K12,O12) -> 0 | AG12: =AVERAGE(S12,W12) -> 0 | AH12: =AVERAGE(AA12,AE12) -> 0 | AI12: =AF12*0.6+AG12*0.25+AH12*0.15 -> 0 | AJ12: =IFERROR(LOOKUP(AI12,'Setup & Assumptions'!$G$19:$G$23,'Setup & Assumptions'!$H$19:$H$23),0) -> 0

Sheet Events & Sponsorship KPIs
B2: Events & Sponsorship — KPI Scorecard (Quarterly)
B3: FOCUS: Close sponsors + influencer deals. Tier 1 = deal closing (sponsors, revenue, influencer deals). Tier 2 = event execution. Tier 3 = quality.
D5: TIER 1 — OUTCOME (60%) | P5: TIER 2 — EXECUTION (25%) | AB5: TIER 3 — QUALITY (15%) | AJ5: WEIGHTED SCORE
D6: # Sponsors Closed | H6: Sponsorship Revenue (QAR) | L6: # Influencer Deals Closed | P6: Events Delivered | T6: Event-attributed Walk-ins | X6: On-Budget Rate | AB6: On-Time Delivery | AF6: Attendee Feedback (/10)
B7: Person | C7: Role | D7: 6-Mo Avg | E7: Target | F7: Actual | G7: % | H7: 6-Mo Avg | I7: Target | J7: Actual | K7: % | L7: 6-Mo Avg | M7: Target | N7: Actual | O7: % | P7: 6-Mo Avg | Q7: Target | R7: Actual | S7: % | T7: 6-Mo Avg | U7: Target | V7: Actual | W7: % | X7: 6-Mo Avg | Y7: Target | Z7: Actual | AA7: % | AB7: 6-Mo Avg | AC7: Target | AD7: Actual | AE7: % | AF7: 6-Mo Avg | AG7: Target | AH7: Actual | AI7: % | AJ7: Tier 1 | AK7: Tier 2 | AL7: Tier 3 | AM7: Total | AN7: Modifier
B8: Janna | C8: Events / Sponsorship | D8: 3 | E8: =5 -> 5 | G8: =IFERROR(F8/E8,0) -> 0 | H8: 40000 | I8: =H8*1.25 -> 50000 | K8: =IFERROR(J8/I8,0) -> 0 | L8: 4 | M8: =8 -> 8 | O8: =IFERROR(N8/M8,0) -> 0 | P8: 10 | Q8: =12 -> 12 | S8: =IFERROR(R8/Q8,0) -> 0 | T8: 150 | U8: =T8*1.3 -> 195 | W8: =IFERROR(V8/U8,0) -> 0 | X8: 0.85 | Y8: =0.9 -> 0.9 | AA8: =IFERROR(Z8/Y8,0) -> 0 | AB8: 0.9 | AC8: =0.95 -> 0.95 | AE8: =IFERROR(AD8/AC8,0) -> 0 | AF8: 7.5 | AG8: =8 -> 8 | AI8: =IFERROR(AH8/AG8,0) -> 0 | AJ8: =AVERAGE(G8,K8,O8) -> 0 | AK8: =AVERAGE(S8,W8,AA8) -> 0 | AL8: =AVERAGE(AE8,AI8) -> 0 | AM8: =AJ8*0.6+AK8*0.25+AL8*0.15 -> 0 | AN8: =IFERROR(LOOKUP(AM8,'Setup & Assumptions'!$G$19:$G$23,'Setup & Assumptions'!$H$19:$H$23),0) -> 0

Sheet Sales & Commission
B2: Quarterly Sales Gate & Commission Calculation
B3: HARD GATE: if a brand hits below 100% of sales target, ZERO commission for everyone on that brand.
B5: BRAND SALES & POOL | I5: PER-ROLE COMMISSION (QAR)
B6: Brand | C6: Sales Target (QAR) | D6: Sales Actual (QAR) | E6: % vs Target | F6: Gate Unlock % | G6: Brand Pool (1.5%) | H6: Unlocked Pool | I6: AM | J6: Media Buyer | K6: Mktg Mgr | L6: Creative Dir. | M6: Designer | N6: Events | O6: Videographer | P6: Reserve | Q6: Total Paid | R6: Notes
B7: VO2 Gym Ladies | C7: 1800000 | E7: =IFERROR(D7/C7,0) -> 0 | F7: =IFERROR(LOOKUP(E7,'Setup & Assumptions'!$C$11:$C$14,'Setup & Assumptions'!$D$11:$D$14),0) -> 0 | G7: =D7*'Setup & Assumptions'!$C$7 -> 0 | H7: =G7*F7 -> 0 | I7: =H7*'Setup & Assumptions'!$G$7*'AM Organic KPIs'!BL8 -> 0 | J7: =H7*'Setup & Assumptions'!$G$8*'Media Buyer Paid KPIs'!AF8 -> 0 | K7: =H7*'Setup & Assumptions'!$G$9*AVERAGE('AM Organic KPIs'!$BL$8:$BL$16,'Media Buyer Paid KPIs'!$AF$8:$AF$16,'Creative Team KPIs'!$AJ$8:$AJ$12,'Events & Sponsorship KPIs'!$AN$8) -> 0 | L7: =H7*'Setup & Assumptions'!$G$10*'Creative Team KPIs'!$AJ$8 -> 0 | M7: =H7*'Setup & Assumptions'!$G$11*IFERROR(VLOOKUP('Setup & Assumptions'!M8,'Creative Team KPIs'!$B$8:$AJ$12,35,FALSE()),0) -> 0 | N7: =H7*'Setup & Assumptions'!$G$12*'Events & Sponsorship KPIs'!$AN$8*IF('Setup & Assumptions'!N8="Yes",1,0) -> 0 | O7: =H7*'Setup & Assumptions'!$G$13*'Creative Team KPIs'!$AJ$9 -> 0 | P7: =H7*'Setup & Assumptions'!$G$14 -> 0 | Q7: =SUM(I7:P7) -> 0
B8: VO2 Gym Men | C8: 1200000 | E8: =IFERROR(D8/C8,0) -> 0 | F8: =IFERROR(LOOKUP(E8,'Setup & Assumptions'!$C$11:$C$14,'Setup & Assumptions'!$D$11:$D$14),0) -> 0 | G8: =D8*'Setup & Assumptions'!$C$7 -> 0 | H8: =G8*F8 -> 0 | I8: =H8*'Setup & Assumptions'!$G$7*'AM Organic KPIs'!BL9 -> 0 | J8: =H8*'Setup & Assumptions'!$G$8*'Media Buyer Paid KPIs'!AF9 -> 0 | K8: =H8*'Setup & Assumptions'!$G$9*AVERAGE('AM Organic KPIs'!$BL$8:$BL$16,'Media Buyer Paid KPIs'!$AF$8:$AF$16,'Creative Team KPIs'!$AJ$8:$AJ$12,'Events & Sponsorship KPIs'!$AN$8) -> 0 | L8: =H8*'Setup & Assumptions'!$G$10*'Creative Team KPIs'!$AJ$8 -> 0 | M8: =H8*'Setup & Assumptions'!$G$11*IFERROR(VLOOKUP('Setup & Assumptions'!M9,'Creative Team KPIs'!$B$8:$AJ$12,35,FALSE()),0) -> 0 | N8: =H8*'Setup & Assumptions'!$G$12*'Events & Sponsorship KPIs'!$AN$8*IF('Setup & Assumptions'!N9="Yes",1,0) -> 0 | O8: =H8*'Setup & Assumptions'!$G$13*'Creative Team KPIs'!$AJ$9 -> 0 | P8: =H8*'Setup & Assumptions'!$G$14 -> 0 | Q8: =SUM(I8:P8) -> 0
B9: The Venue Ladies | C9: 2158296 | E9: =IFERROR(D9/C9,0) -> 0 | F9: =IFERROR(LOOKUP(E9,'Setup & Assumptions'!$C$11:$C$14,'Setup & Assumptions'!$D$11:$D$14),0) -> 0 | G9: =D9*'Setup & Assumptions'!$C$7 -> 0 | H9: =G9*F9 -> 0 | I9: =H9*'Setup & Assumptions'!$G$7*'AM Organic KPIs'!BL10 -> 0 | J9: =H9*'Setup & Assumptions'!$G$8*'Media Buyer Paid KPIs'!AF10 -> 0 | K9: =H9*'Setup & Assumptions'!$G$9*AVERAGE('AM Organic KPIs'!$BL$8:$BL$16,'Media Buyer Paid KPIs'!$AF$8:$AF$16,'Creative Team KPIs'!$AJ$8:$AJ$12,'Events & Sponsorship KPIs'!$AN$8) -> 0 | L9: =H9*'Setup & Assumptions'!$G$10*'Creative Team KPIs'!$AJ$8 -> 0 | M9: =H9*'Setup & Assumptions'!$G$11*IFERROR(VLOOKUP('Setup & Assumptions'!M10,'Creative Team KPIs'!$B$8:$AJ$12,35,FALSE()),0) -> 0 | N9: =H9*'Setup & Assumptions'!$G$12*'Events & Sponsorship KPIs'!$AN$8*IF('Setup & Assumptions'!N10="Yes",1,0) -> 0 | O9: =H9*'Setup & Assumptions'!$G$13*'Creative Team KPIs'!$AJ$9 -> 0 | P9: =H9*'Setup & Assumptions'!$G$14 -> 0 | Q9: =SUM(I9:P9) -> 0
B10: The Venue Men | C10: 2776147 | E10: =IFERROR(D10/C10,0) -> 0 | F10: =IFERROR(LOOKUP(E10,'Setup & Assumptions'!$C$11:$C$14,'Setup & Assumptions'!$D$11:$D$14),0) -> 0 | G10: =D10*'Setup & Assumptions'!$C$7 -> 0 | H10: =G10*F10 -> 0 | I10: =H10*'Setup & Assumptions'!$G$7*'AM Organic KPIs'!BL11 -> 0 | J10: =H10*'Setup & Assumptions'!$G$8*'Media Buyer Paid KPIs'!AF11 -> 0 | K10: =H10*'Setup & Assumptions'!$G$9*AVERAGE('AM Organic KPIs'!$BL$8:$BL$16,'Media Buyer Paid KPIs'!$AF$8:$AF$16,'Creative Team KPIs'!$AJ$8:$AJ$12,'Events & Sponsorship KPIs'!$AN$8) -> 0 | L10: =H10*'Setup & Assumptions'!$G$10*'Creative Team KPIs'!$AJ$8 -> 0 | M10: =H10*'Setup & Assumptions'!$G$11*IFERROR(VLOOKUP('Setup & Assumptions'!M11,'Creative Team KPIs'!$B$8:$AJ$12,35,FALSE()),0) -> 0 | N10: =H10*'Setup & Assumptions'!$G$12*'Events & Sponsorship KPIs'!$AN$8*IF('Setup & Assumptions'!N11="Yes",1,0) -> 0 | O10: =H10*'Setup & Assumptions'!$G$13*'Creative Team KPIs'!$AJ$9 -> 0 | P10: =H10*'Setup & Assumptions'!$G$14 -> 0 | Q10: =SUM(I10:P10) -> 0
B11: M Active Ladies | C11: 1345634 | E11: =IFERROR(D11/C11,0) -> 0 | F11: =IFERROR(LOOKUP(E11,'Setup & Assumptions'!$C$11:$C$14,'Setup & Assumptions'!$D$11:$D$14),0) -> 0 | G11: =D11*'Setup & Assumptions'!$C$7 -> 0 | H11: =G11*F11 -> 0 | I11: =H11*'Setup & Assumptions'!$G$7*'AM Organic KPIs'!BL12 -> 0 | J11: =H11*'Setup & Assumptions'!$G$8*'Media Buyer Paid KPIs'!AF12 -> 0 | K11: =H11*'Setup & Assumptions'!$G$9*AVERAGE('AM Organic KPIs'!$BL$8:$BL$16,'Media Buyer Paid KPIs'!$AF$8:$AF$16,'Creative Team KPIs'!$AJ$8:$AJ$12,'Events & Sponsorship KPIs'!$AN$8) -> 0 | L11: =H11*'Setup & Assumptions'!$G$10*'Creative Team KPIs'!$AJ$8 -> 0 | M11: =H11*'Setup & Assumptions'!$G$11*IFERROR(VLOOKUP('Setup & Assumptions'!M12,'Creative Team KPIs'!$B$8:$AJ$12,35,FALSE()),0) -> 0 | N11: =H11*'Setup & Assumptions'!$G$12*'Events & Sponsorship KPIs'!$AN$8*IF('Setup & Assumptions'!N12="Yes",1,0) -> 0 | O11: =H11*'Setup & Assumptions'!$G$13*'Creative Team KPIs'!$AJ$9 -> 0 | P11: =H11*'Setup & Assumptions'!$G$14 -> 0 | Q11: =SUM(I11:P11) -> 0
B12: M Active Club | C12: 2238994 | E12: =IFERROR(D12/C12,0) -> 0 | F12: =IFERROR(LOOKUP(E12,'Setup & Assumptions'!$C$11:$C$14,'Setup & Assumptions'!$D$11:$D$14),0) -> 0 | G12: =D12*'Setup & Assumptions'!$C$7 -> 0 | H12: =G12*F12 -> 0 | I12: =H12*'Setup & Assumptions'!$G$7*'AM Organic KPIs'!BL13 -> 0 | J12: =H12*'Setup & Assumptions'!$G$8*'Media Buyer Paid KPIs'!AF13 -> 0 | K12: =H12*'Setup & Assumptions'!$G$9*AVERAGE('AM Organic KPIs'!$BL$8:$BL$16,'Media Buyer Paid KPIs'!$AF$8:$AF$16,'Creative Team KPIs'!$AJ$8:$AJ$12,'Events & Sponsorship KPIs'!$AN$8) -> 0 | L12: =H12*'Setup & Assumptions'!$G$10*'Creative Team KPIs'!$AJ$8 -> 0 | M12: =H12*'Setup & Assumptions'!$G$11*IFERROR(VLOOKUP('Setup & Assumptions'!M13,'Creative Team KPIs'!$B$8:$AJ$12,35,FALSE()),0) -> 0 | N12: =H12*'Setup & Assumptions'!$G$12*'Events & Sponsorship KPIs'!$AN$8*IF('Setup & Assumptions'!N13="Yes",1,0) -> 0 | O12: =H12*'Setup & Assumptions'!$G$13*'Creative Team KPIs'!$AJ$9 -> 0 | P12: =H12*'Setup & Assumptions'!$G$14 -> 0 | Q12: =SUM(I12:P12) -> 0
B13: Aspire Active Dome | C13: 830970 | E13: =IFERROR(D13/C13,0) -> 0 | F13: =IFERROR(LOOKUP(E13,'Setup & Assumptions'!$C$11:$C$14,'Setup & Assumptions'!$D$11:$D$14),0) -> 0 | G13: =D13*'Setup & Assumptions'!$C$7 -> 0 | H13: =G13*F13 -> 0 | I13: =H13*'Setup & Assumptions'!$G$7*'AM Organic KPIs'!BL14 -> 0 | J13: =H13*'Setup & Assumptions'!$G$8*'Media Buyer Paid KPIs'!AF14 -> 0 | K13: =H13*'Setup & Assumptions'!$G$9*AVERAGE('AM Organic KPIs'!$BL$8:$BL$16,'Media Buyer Paid KPIs'!$AF$8:$AF$16,'Creative Team KPIs'!$AJ$8:$AJ$12,'Events & Sponsorship KPIs'!$AN$8) -> 0 | L13: =H13*'Setup & Assumptions'!$G$10*'Creative Team KPIs'!$AJ$8 -> 0 | M13: =H13*'Setup & Assumptions'!$G$11*IFERROR(VLOOKUP('Setup & Assumptions'!M14,'Creative Team KPIs'!$B$8:$AJ$12,35,FALSE()),0) -> 0 | N13: =H13*'Setup & Assumptions'!$G$12*'Events & Sponsorship KPIs'!$AN$8*IF('Setup & Assumptions'!N14="Yes",1,0) -> 0 | O13: =H13*'Setup & Assumptions'!$G$13*'Creative Team KPIs'!$AJ$9 -> 0 | P13: =H13*'Setup & Assumptions'!$G$14 -> 0 | Q13: =SUM(I13:P13) -> 0
B14: Aspire Active Ladies | C14: 2338272 | E14: =IFERROR(D14/C14,0) -> 0 | F14: =IFERROR(LOOKUP(E14,'Setup & Assumptions'!$C$11:$C$14,'Setup & Assumptions'!$D$11:$D$14),0) -> 0 | G14: =D14*'Setup & Assumptions'!$C$7 -> 0 | H14: =G14*F14 -> 0 | I14: =H14*'Setup & Assumptions'!$G$7*'AM Organic KPIs'!BL15 -> 0 | J14: =H14*'Setup & Assumptions'!$G$8*'Media Buyer Paid KPIs'!AF15 -> 0 | K14: =H14*'Setup & Assumptions'!$G$9*AVERAGE('AM Organic KPIs'!$BL$8:$BL$16,'Media Buyer Paid KPIs'!$AF$8:$AF$16,'Creative Team KPIs'!$AJ$8:$AJ$12,'Events & Sponsorship KPIs'!$AN$8) -> 0 | L14: =H14*'Setup & Assumptions'!$G$10*'Creative Team KPIs'!$AJ$8 -> 0 | M14: =H14*'Setup & Assumptions'!$G$11*IFERROR(VLOOKUP('Setup & Assumptions'!M15,'Creative Team KPIs'!$B$8:$AJ$12,35,FALSE()),0) -> 0 | N14: =H14*'Setup & Assumptions'!$G$12*'Events & Sponsorship KPIs'!$AN$8*IF('Setup & Assumptions'!N15="Yes",1,0) -> 0 | O14: =H14*'Setup & Assumptions'!$G$13*'Creative Team KPIs'!$AJ$9 -> 0 | P14: =H14*'Setup & Assumptions'!$G$14 -> 0 | Q14: =SUM(I14:P14) -> 0
